<?xml version="1.0" ?>
<robot name="iiwa_with_gripper" xmlns:xacro="http://www.ros.org/wiki/xacro">

  <xacro:include filename="$(find iiwa_with_gripper_description)/urdf/materials.xacro" />
  <xacro:include filename="$(find iiwa_with_gripper_description)/urdf/iiwa_with_gripper.trans" />
  <xacro:include filename="$(find iiwa_with_gripper_description)/urdf/iiwa_with_gripper.gazebo" />
  <link name="base_link">
    <inertial>
      <origin xyz="0.006965322374704147 -0.010760554559419669 0.06950676619175733" rpy="0 0 0"/>
      <mass value="5.476316363546272"/>
      <inertia ixx="0.02889" iyy="0.026199" izz="0.03348" ixy="0.003002" iyz="0.000568" ixz="-0.000368"/>
    </inertial>
    <visual>
      <origin xyz="0 0 0" rpy="0 0 0"/>
      <geometry>
        <mesh filename="package://iiwa_with_gripper_description/meshes/base_link.stl" scale="0.001 0.001 0.001"/>
      </geometry>
      <material name="silver"/>
    </visual>
    <collision>
      <origin xyz="0 0 0" rpy="0 0 0"/>
      <geometry>
        <mesh filename="package://iiwa_with_gripper_description/meshes/base_link.stl" scale="0.001 0.001 0.001"/>
      </geometry>
    </collision>
  </link>

  <link name="link1_1">
    <inertial>
      <origin xyz="-0.017943018054847274 -0.028638803355450302 0.1324037509841229" rpy="0 0 0"/>
      <mass value="4.1085979543107625"/>
      <inertia ixx="0.033064" iyy="0.033192" izz="0.012327" ixy="0.000132" iyz="0.004174" ixz="0.002615"/>
    </inertial>
    <visual>
      <origin xyz="5e-06 -1e-06 -0.1455" rpy="0 0 0"/>
      <geometry>
        <mesh filename="package://iiwa_with_gripper_description/meshes/link1_1.stl" scale="0.001 0.001 0.001"/>
      </geometry>
      <material name="silver"/>
    </visual>
    <collision>
      <origin xyz="5e-06 -1e-06 -0.1455" rpy="0 0 0"/>
      <geometry>
        <mesh filename="package://iiwa_with_gripper_description/meshes/link1_1.stl" scale="0.001 0.001 0.001"/>
      </geometry>
    </collision>
  </link>

  <link name="link2_1">
    <inertial>
      <origin xyz="0.027730554612854612 0.04397318850973551 0.05880227691865292" rpy="0 0 0"/>
      <mass value="3.9516031301561854"/>
      <inertia ixx="0.030525" iyy="0.030489" izz="0.011018" ixy="-8.9e-05" iyz="0.004124" ixz="0.002623"/>
    </inertial>
    <visual>
      <origin xyz="0.005314 0.008473 -0.358" rpy="0 0 0"/>
      <geometry>
        <mesh filename="package://iiwa_with_gripper_description/meshes/link2_1.stl" scale="0.001 0.001 0.001"/>
      </geometry>
      <material name="silver"/>
    </visual>
    <collision>
      <origin xyz="0.005314 0.008473 -0.358" rpy="0 0 0"/>
      <geometry>
        <mesh filename="package://iiwa_with_gripper_description/meshes/link2_1.stl" scale="0.001 0.001 0.001"/>
      </geometry>
    </collision>
  </link>

  <link name="link3_1">
    <inertial>
      <origin xyz="0.025051478850338406 -0.015696019116518925 0.13649751267814747" rpy="0 0 0"/>
      <mass value="3.1751522797798235"/>
      <inertia ixx="0.024168" iyy="0.024723" izz="0.007609" ixy="0.000572" iyz="0.002588" ixz="-0.00413"/>
    </inertial>
    <visual>
      <origin xyz="5e-06 -1e-06 -0.5525" rpy="0 0 0"/>
      <geometry>
        <mesh filename="package://iiwa_with_gripper_description/meshes/link3_1.stl" scale="0.001 0.001 0.001"/>
      </geometry>
      <material name="silver"/>
    </visual>
    <collision>
      <origin xyz="5e-06 -1e-06 -0.5525" rpy="0 0 0"/>
      <geometry>
        <mesh filename="package://iiwa_with_gripper_description/meshes/link3_1.stl" scale="0.001 0.001 0.001"/>
      </geometry>
    </collision>
  </link>

  <link name="link4_1">
    <inertial>
      <origin xyz="-0.03793408371324007 0.02376733466078998 0.0674187772182614" rpy="0 0 0"/>
      <mass value="2.7394199863147835"/>
      <inertia ixx="0.016623" iyy="0.016976" izz="0.006138" ixy="0.000364" iyz="0.001512" ixz="-0.002413"/>
    </inertial>
    <visual>
      <origin xyz="-0.008893 0.005574 -0.778" rpy="0 0 0"/>
      <geometry>
        <mesh filename="package://iiwa_with_gripper_description/meshes/link4_1.stl" scale="0.001 0.001 0.001"/>
      </geometry>
      <material name="silver"/>
    </visual>
    <collision>
      <origin xyz="-0.008893 0.005574 -0.778" rpy="0 0 0"/>
      <geometry>
        <mesh filename="package://iiwa_with_gripper_description/meshes/link4_1.stl" scale="0.001 0.001 0.001"/>
      </geometry>
    </collision>
  </link>

  <link name="link5_1">
    <inertial>
      <origin xyz="-0.018059916116281608 0.01145722636903425 0.08546976144259932" rpy="0 0 0"/>
      <mass value="1.6937518930824942"/>
      <inertia ixx="0.00909" iyy="0.009693" izz="0.004469" ixy="0.000619" iyz="-0.00164" ixz="0.002619"/>
    </inertial>
    <visual>
      <origin xyz="5e-06 -1e-06 -0.9525" rpy="0 0 0"/>
      <geometry>
        <mesh filename="package://iiwa_with_gripper_description/meshes/link5_1.stl" scale="0.001 0.001 0.001"/>
      </geometry>
      <material name="silver"/>
    </visual>
    <collision>
      <origin xyz="5e-06 -1e-06 -0.9525" rpy="0 0 0"/>
      <geometry>
        <mesh filename="package://iiwa_with_gripper_description/meshes/link5_1.stl" scale="0.001 0.001 0.001"/>
      </geometry>
    </collision>
  </link>

  <link name="link6_1">
    <inertial>
      <origin xyz="0.060197961567838416 -0.03771691538484422 0.0005655510153361742" rpy="0 0 0"/>
      <mass value="1.8087048119470246"/>
      <inertia ixx="0.004745" iyy="0.004836" izz="0.003567" ixy="9.4e-05" iyz="-0.00013" ixz="0.000207"/>
    </inertial>
    <visual>
      <origin xyz="0.059916 -0.037538 -1.178" rpy="0 0 0"/>
      <geometry>
        <mesh filename="package://iiwa_with_gripper_description/meshes/link6_1.stl" scale="0.001 0.001 0.001"/>
      </geometry>
      <material name="silver"/>
    </visual>
    <collision>
      <origin xyz="0.059916 -0.037538 -1.178" rpy="0 0 0"/>
      <geometry>
        <mesh filename="package://iiwa_with_gripper_description/meshes/link6_1.stl" scale="0.001 0.001 0.001"/>
      </geometry>
    </collision>
  </link>

  <link name="link7_1">
    <inertial>
      <origin xyz="-8.566076938427869e-05 -1.6648615005243726e-05 0.02726331885121902" rpy="0 0 0"/>
      <mass value="0.3112293546238468"/>
      <inertia ixx="0.000222" iyy="0.000223" izz="0.000342" ixy="-1e-06" iyz="0.0" ixz="0.0"/>
    </inertial>
    <visual>
      <origin xyz="5e-06 -1e-06 -1.2491" rpy="0 0 0"/>
      <geometry>
        <mesh filename="package://iiwa_with_gripper_description/meshes/link7_1.stl" scale="0.001 0.001 0.001"/>
      </geometry>
      <material name="silver"/>
    </visual>
    <collision>
      <origin xyz="5e-06 -1e-06 -1.2491" rpy="0 0 0"/>
      <geometry>
        <mesh filename="package://iiwa_with_gripper_description/meshes/link7_1.stl" scale="0.001 0.001 0.001"/>
      </geometry>
    </collision>
  </link>

  <link name="gripper_base_1">
    <inertial>
      <origin xyz="3.696945411962817e-07 -2.838668831751647e-07 0.025340357617523068" rpy="0 0 0"/>
      <mass value="0.14502326695982184"/>
      <inertia ixx="0.000113" iyy="0.000133" izz="0.000146" ixy="1.1e-05" iyz="-0.0" ixz="-0.0"/>
    </inertial>
    <visual>
      <origin xyz="5e-06 -1e-06 -1.304" rpy="0 0 0"/>
      <geometry>
        <mesh filename="package://iiwa_with_gripper_description/meshes/gripper_base_1.stl" scale="0.001 0.001 0.001"/>
      </geometry>
      <material name="silver"/>
    </visual>
    <collision>
      <origin xyz="5e-06 -1e-06 -1.304" rpy="0 0 0"/>
      <geometry>
        <mesh filename="package://iiwa_with_gripper_description/meshes/gripper_base_1.stl" scale="0.001 0.001 0.001"/>
      </geometry>
    </collision>
  </link>

  <link name="gripper_axis_1">
    <inertial>
      <origin xyz="-0.24653063030548122 -0.10569728386693174 -3.943512183468556e-13" rpy="0 0 0"/>
      <mass value="0.013076879420567428"/>
      <inertia ixx="1e-06" iyy="5e-06" izz="6e-06" ixy="2e-06" iyz="-0.0" ixz="-0.0"/>
    </inertial>
    <visual>
      <origin xyz="-0.246526 -0.105698 -1.346" rpy="0 0 0"/>
      <geometry>
        <mesh filename="package://iiwa_with_gripper_description/meshes/gripper_axis_1.stl" scale="0.001 0.001 0.001"/>
      </geometry>
      <material name="silver"/>
    </visual>
    <collision>
      <origin xyz="-0.246526 -0.105698 -1.346" rpy="0 0 0"/>
      <geometry>
        <mesh filename="package://iiwa_with_gripper_description/meshes/gripper_axis_1.stl" scale="0.001 0.001 0.001"/>
      </geometry>
    </collision>
  </link>

  <link name="gripper_finger1_1">
    <inertial>
      <origin xyz="-7.522186935857434e-05 -0.015319651825661716 0.04015659424597029" rpy="0 0 0"/>
      <mass value="0.056756377676662674"/>
      <inertia ixx="8.2e-05" iyy="7.6e-05" izz="1.2e-05" ixy="-3e-06" iyz="5e-06" ixz="5e-06"/>
    </inertial>
    <visual>
      <origin xyz="5e-06 -1e-06 -1.346" rpy="0 0 0"/>
      <geometry>
        <mesh filename="package://iiwa_with_gripper_description/meshes/gripper_finger1_1.stl" scale="0.001 0.001 0.001"/>
      </geometry>
      <material name="silver"/>
    </visual>
    <collision>
      <origin xyz="5e-06 -1e-06 -1.346" rpy="0 0 0"/>
      <geometry>
        <mesh filename="package://iiwa_with_gripper_description/meshes/gripper_finger1_1.stl" scale="0.001 0.001 0.001"/>
      </geometry>
    </collision>
  </link>

  <link name="grippe_finger2_1">
    <inertial>
      <origin xyz="-5.6963165186682546e-05 0.015028330719705208 0.040266373725741156" rpy="0 0 0"/>
      <mass value="0.0567564113627171"/>
      <inertia ixx="8.2e-05" iyy="7.6e-05" izz="1.1e-05" ixy="-3e-06" iyz="-4e-06" ixz="-5e-06"/>
    </inertial>
    <visual>
      <origin xyz="5e-06 -1e-06 -1.346" rpy="0 0 0"/>
      <geometry>
        <mesh filename="package://iiwa_with_gripper_description/meshes/grippe_finger2_1.stl" scale="0.001 0.001 0.001"/>
      </geometry>
      <material name="silver"/>
    </visual>
    <collision>
      <origin xyz="5e-06 -1e-06 -1.346" rpy="0 0 0"/>
      <geometry>
        <mesh filename="package://iiwa_with_gripper_description/meshes/grippe_finger2_1.stl" scale="0.001 0.001 0.001"/>
      </geometry>
    </collision>
  </link>

  <joint name="revolute1" type="continuous">
    <origin xyz="-5e-06 1e-06 0.1455" rpy="0 0 0"/>
    <parent link="base_link"/>
    <child link="link1_1"/>
    <axis xyz="0.0 0.0 1.0"/>
  </joint>

  <joint name="revolute2" type="continuous">
    <origin xyz="-0.005309 -0.008474 0.2125" rpy="0 0 0"/>
    <parent link="link1_1"/>
    <child link="link2_1"/>
    <axis xyz="0.530942 0.847408 0.0"/>
  </joint>

  <joint name="revolute3" type="continuous">
    <origin xyz="0.005309 0.008474 0.1945" rpy="0 0 0"/>
    <parent link="link2_1"/>
    <child link="link3_1"/>
    <axis xyz="0.0 0.0 1.0"/>
  </joint>

  <joint name="revolute4" type="continuous">
    <origin xyz="0.008898 -0.005575 0.2255" rpy="0 0 0"/>
    <parent link="link3_1"/>
    <child link="link4_1"/>
    <axis xyz="-0.847408 0.530942 0.0"/>
  </joint>

  <joint name="revolute5" type="continuous">
    <origin xyz="-0.008898 0.005575 0.1745" rpy="0 0 0"/>
    <parent link="link4_1"/>
    <child link="link5_1"/>
    <axis xyz="0.0 0.0 1.0"/>
  </joint>

  <joint name="revolute6" type="continuous">
    <origin xyz="-0.059911 0.037537 0.2255" rpy="0 0 0"/>
    <parent link="link5_1"/>
    <child link="link6_1"/>
    <axis xyz="0.847408 -0.530942 0.0"/>
  </joint>

  <joint name="revolute7" type="continuous">
    <origin xyz="0.059911 -0.037537 0.0711" rpy="0 0 0"/>
    <parent link="link6_1"/>
    <child link="link7_1"/>
    <axis xyz="0.0 0.0 1.0"/>
  </joint>

  <joint name="revolute8" type="continuous">
    <origin xyz="0.0 0.0 0.0549" rpy="0 0 0"/>
    <parent link="link7_1"/>
    <child link="gripper_base_1"/>
    <axis xyz="0.0 -0.0 -1.0"/>
  </joint>

  <joint name="rigid9" type="fixed">
    <origin xyz="0.246531 0.105697 0.042" rpy="0 0 0"/>
    <parent link="gripper_base_1"/>
    <child link="gripper_axis_1"/>
  </joint>

  <joint name="revolute10" type="revolute">
    <origin xyz="-0.246531 -0.105697 0.0" rpy="0 0 0"/>
    <parent link="gripper_axis_1"/>
    <child link="gripper_finger1_1"/>
    <axis xyz="-0.90946 0.415791 -0.0"/>
    <limit upper="0.0" lower="-0.523599" effort="100" velocity="100"/>
  </joint>

  <joint name="revolute11" type="revolute">
    <origin xyz="-0.246531 -0.105697 0.0" rpy="0 0 0"/>
    <parent link="gripper_axis_1"/>
    <child link="grippe_finger2_1"/>
    <axis xyz="-0.90946 0.415791 -0.0"/>
    <limit upper="0.523599" lower="0.0" effort="100" velocity="100"/>
  </joint>

</robot>
